---
title: 处理异常的正常姿势
date: 2023-04-07 11:02:09
permalink: /pages/2ecb76/
categories:
  - java基础
  - 异常
tags:
  - 
author: 
  name: xugaoyi
  link: https://github.com/xugaoyi
---
[https://www.cnblogs.com/tsiangleo/p/4396574.html](https://www.cnblogs.com/tsiangleo/p/4396574.html)

## 异常实践

提示

在 Java 中处理异常并不是一个简单的事情。不仅仅初学者很难理解，即使一些有经验的开发者也需要花费很多时间来思考如何处理异常，包括需要处理哪些异常，怎样处理等等。这也是绝大多数开发团队都会制定一些规则来规范进行异常处理的原因。

当你抛出或捕获异常的时候，有很多不同的情况需要考虑，而且大部分事情都是为了改善代码的可读性或者 API 的可用性。

异常不仅仅是一个错误控制机制，也是一个通信媒介。因此，为了和同事更好的合作，一个团队必须要制定出一个最佳实践和规则，只有这样，团队成员才能理解这些通用概念，同时在工作中使用它。

这里给出几个被很多团队使用的异常处理最佳实践。

### [#](#只针对不正常的情况才使用异常) 只针对不正常的情况才使用异常

> 异常只应该被用于不正常的条件，它们永远不应该被用于正常的控制流。《阿里手册》中：【强制】Java 类库中定义的可以通过预检查方式规避的RuntimeException异常不应该通过catch 的方式来处理，比如：NullPointerException，IndexOutOfBoundsException等等。

比如，在解析字符串形式的数字时，可能存在数字格式错误，不得通过catch Exception来实现

- 代码1

```java
if (obj != null) {
  //...
}
```

- 代码2

```java
try { 
  obj.method(); 
} catch (NullPointerException e) {
  //...
}
```

主要原因有三点：

- 异常机制的设计初衷是用于不正常的情况，所以很少会会JVM实现试图对它们的性能进行优化。所以，创建、抛出和捕获异常的开销是很昂贵的。
- 把代码放在try-catch中返回阻止了JVM实现本来可能要执行的某些特定的优化。
- 对数组进行遍历的标准模式并不会导致冗余的检查，有些现代的JVM实现会将它们优化掉。

### [#](#在-finally-块中清理资源或者使用-try-with-resource-语句) 在 finally 块中清理资源或者使用 try-with-resource 语句

当使用类似InputStream这种需要使用后关闭的资源时，一个常见的错误就是在try块的最后关闭资源。

- 错误示例

```java
public void doNotCloseResourceInTry() {
    FileInputStream inputStream = null;
    try {
        File file = new File("./tmp.txt");
        inputStream = new FileInputStream(file);
        // use the inputStream to read a file
        // do NOT do this
        inputStream.close();
    } catch (FileNotFoundException e) {
        log.error(e);
    } catch (IOException e) {
        log.error(e);
    }
}
```

问题就是，只有没有异常抛出的时候，这段代码才可以正常工作。try 代码块内代码会正常执行，并且资源可以正常关闭。但是，使用 try 代码块是有原因的，一般调用一个或多个可能抛出异常的方法，而且，你自己也可能会抛出一个异常，这意味着代码可能不会执行到 try 代码块的最后部分。结果就是，你并没有关闭资源。

所以，你应该把清理工作的代码放到 finally 里去，或者使用 try-with-resource 特性。

- 方法一：使用 finally 代码块

与前面几行 try 代码块不同，finally 代码块总是会被执行。不管 try 代码块成功执行之后还是你在 catch 代码块中处理完异常后都会执行。因此，你可以确保你清理了所有打开的资源。

```java
public void closeResourceInFinally() {
    FileInputStream inputStream = null;
    try {
        File file = new File("./tmp.txt");
        inputStream = new FileInputStream(file);
        // use the inputStream to read a file
    } catch (FileNotFoundException e) {
        log.error(e);
    } finally {
        if (inputStream != null) {
            try {
                inputStream.close();
            } catch (IOException e) {
                log.error(e);
            }
        }
    }
}
```

- 方法二：Java 7 的 try-with-resource 语法

如果你的资源实现了 AutoCloseable 接口，你可以使用这个语法。大多数的 Java 标准资源都继承了这个接口。当你在 try 子句中打开资源，资源会在 try 代码块执行后或异常处理后自动关闭。

```java
public void automaticallyCloseResource() {
    File file = new File("./tmp.txt");
    try (FileInputStream inputStream = new FileInputStream(file);) {
        // use the inputStream to read a file
    } catch (FileNotFoundException e) {
        log.error(e);
    } catch (IOException e) {
        log.error(e);
    }
}
```

### [#](#尽量使用标准的异常) 尽量使用标准的异常

> 代码重用是值得提倡的，这是一条通用规则，异常也不例外。

重用现有的异常有几个好处：

- 它使得你的API更加易于学习和使用，因为它与程序员原来已经熟悉的习惯用法是一致的。
- 对于用到这些API的程序而言，它们的可读性更好，因为它们不会充斥着程序员不熟悉的异常。
- 异常类越少，意味着内存占用越小，并且转载这些类的时间开销也越小。

Java标准异常中有几个是经常被使用的异常。如下表格：

| 异常                            | 使用场合                                   |
| ------------------------------- | ------------------------------------------ |
| IllegalArgumentException        | 参数的值不合适                             |
| IllegalStateException           | 参数的状态不合适                           |
| NullPointerException            | 在null被禁止的情况下参数值为null           |
| IndexOutOfBoundsException       | 下标越界                                   |
| ConcurrentModificationException | 在禁止并发修改的情况下，对象检测到并发修改 |
| UnsupportedOperationException   | 对象不支持客户请求的方法                   |

虽然它们是Java平台库迄今为止最常被重用的异常，但是，在许可的条件下，其它的异常也可以被重用。例如，如果你要实现诸如复数或者矩阵之类的算术对象，那么重用ArithmeticException和NumberFormatException将是非常合适的。如果一个异常满足你的需要，则不要犹豫，使用就可以，不过你一定要确保抛出异常的条件与该异常的文档中描述的条件一致。这种重用必须建立在语义的基础上，而不是名字的基础上。

最后，一定要清楚，选择重用哪一种异常并没有必须遵循的规则。例如，考虑纸牌对象的情形，假设有一个用于发牌操作的方法，它的参数(handSize)是发一手牌的纸牌张数。假设调用者在这个参数中传递的值大于整副牌的剩余张数。那么这种情形既可以被解释为IllegalArgumentException(handSize的值太大)，也可以被解释为IllegalStateException(相对客户的请求而言，纸牌对象的纸牌太少)。

### [#](#对异常进行文档说明) 对异常进行文档说明

> 当在方法上声明抛出异常时，也需要进行文档说明。目的是为了给调用者提供尽可能多的信息，从而可以更好地避免或处理异常。

在 Javadoc 添加 @throws 声明，并且描述抛出异常的场景。

```java
/**
* Method description
* 
* @throws MyBusinessException - businuess exception description
*/
public void doSomething(String input) throws MyBusinessException {
   // ...
}
```

同时，在抛出MyBusinessException 异常时，需要尽可能精确地描述问题和相关信息，这样无论是打印到日志中还是在监控工具中，都能够更容易被人阅读，从而可以更好地定位具体错误信息、错误的严重程度等。

### [#](#优先捕获最具体的异常) 优先捕获最具体的异常

> 大多数 IDE 都可以帮助你实现这个最佳实践。当你尝试首先捕获较不具体的异常时，它们会报告无法访问的代码块。

但问题在于，只有匹配异常的第一个 catch 块会被执行。 因此，如果首先捕获 IllegalArgumentException ，则永远不会到达应该处理更具体的 NumberFormatException 的 catch 块，因为它是 IllegalArgumentException 的子类。

总是优先捕获最具体的异常类，并将不太具体的 catch 块添加到列表的末尾。

你可以在下面的代码片断中看到这样一个 try-catch 语句的例子。 第一个 catch 块处理所有 NumberFormatException 异常，第二个处理所有非 NumberFormatException 异常的IllegalArgumentException 异常。

```java
public void catchMostSpecificExceptionFirst() {
    try {
        doSomething("A message");
    } catch (NumberFormatException e) {
        log.error(e);
    } catch (IllegalArgumentException e) {
        log.error(e)
    }
}
```

### [#](#不要捕获-throwable-类) 不要捕获 Throwable 类

> Throwable 是所有异常和错误的超类。你可以在 catch 子句中使用它，但是你永远不应该这样做！

如果在 catch 子句中使用 Throwable ，它不仅会捕获所有异常，也将捕获所有的错误。JVM 抛出错误，指出不应该由应用程序处理的严重问题。 典型的例子是 OutOfMemoryError 或者 StackOverflowError 。两者都是由应用程序控制之外的情况引起的，无法处理。

所以，最好不要捕获 Throwable ，除非你确定自己处于一种特殊的情况下能够处理错误。

```java
public void doNotCatchThrowable() {
    try {
        // do something
    } catch (Throwable t) {
        // don't do this!
    }
}
```

### [#](#不要忽略异常) 不要忽略异常

> 很多时候，开发者很有自信不会抛出异常，因此写了一个catch块，但是没有做任何处理或者记录日志。

```java
public void doNotIgnoreExceptions() {
    try {
        // do something
    } catch (NumberFormatException e) {
        // this will never happen
    }
}
```

但现实是经常会出现无法预料的异常，或者无法确定这里的代码未来是不是会改动(删除了阻止异常抛出的代码)，而此时由于异常被捕获，使得无法拿到足够的错误信息来定位问题。

合理的做法是至少要记录异常的信息。

```java
public void logAnException() {
    try {
        // do something
    } catch (NumberFormatException e) {
        log.error("This should never happen: " + e); // see this line
    }
}
```

### [#](#不要记录并抛出异常) 不要记录并抛出异常

> 这可能是本文中最常被忽略的最佳实践。

可以发现很多代码甚至类库中都会有捕获异常、记录日志并再次抛出的逻辑。如下：

```java
try {
    new Long("xyz");
} catch (NumberFormatException e) {
    log.error(e);
    throw e;
}
```

这个处理逻辑看着是合理的。但这经常会给同一个异常输出多条日志。如下：

```java
17:44:28,945 ERROR TestExceptionHandling:65 - java.lang.NumberFormatException: For input string: "xyz"
Exception in thread "main" java.lang.NumberFormatException: For input string: "xyz"
at java.lang.NumberFormatException.forInputString(NumberFormatException.java:65)
at java.lang.Long.parseLong(Long.java:589)
at java.lang.Long.(Long.java:965)
at com.stackify.example.TestExceptionHandling.logAndThrowException(TestExceptionHandling.java:63)
at com.stackify.example.TestExceptionHandling.main(TestExceptionHandling.java:58)
```

如上所示，后面的日志也没有附加更有用的信息。如果想要提供更加有用的信息，那么可以将异常包装为自定义异常。

```java
public void wrapException(String input) throws MyBusinessException {
    try {
        // do something
    } catch (NumberFormatException e) {
        throw new MyBusinessException("A message that describes the error.", e);
    }
}
```

因此，仅仅当想要处理异常时才去捕获，否则只需要在方法签名中声明让调用者去处理。

### [#](#包装异常时不要抛弃原始的异常) 包装异常时不要抛弃原始的异常

捕获标准异常并包装为自定义异常是一个很常见的做法。这样可以添加更为具体的异常信息并能够做针对的异常处理。 在你这样做时，请确保将原始异常设置为原因（注：参考下方代码 NumberFormatException e 中的原始异常 e ）。Exception 类提供了特殊的构造函数方法，它接受一个 Throwable 作为参数。否则，你将会丢失堆栈跟踪和原始异常的消息，这将会使分析导致异常的异常事件变得困难。

```java
public void wrapException(String input) throws MyBusinessException {
    try {
        // do something
    } catch (NumberFormatException e) {
        throw new MyBusinessException("A message that describes the error.", e);
    }
}
```

### [#](#不要使用异常控制程序的流程) 不要使用异常控制程序的流程

不应该使用异常控制应用的执行流程，例如，本应该使用if语句进行条件判断的情况下，你却使用异常处理，这是非常不好的习惯，会严重影响应用的性能。

### [#](#不要在finally块中使用return。) 不要在finally块中使用return。

try块中的return语句执行成功后，并不马上返回，而是继续执行finally块中的语句，如果此处存在return语句，则在此直接返回，无情丢弃掉try块中的返回点。

如下是一个反例：

```java
private int x = 0;
public int checkReturn() {
    try {
        // x等于1，此处不返回
        return ++x;
    } finally {
        // 返回的结果是2
        return ++x;
    }
}
```

------

著作权归@pdai所有 原文链接：https://pdai.tech/md/java/basic/java-basic-x-exception.html